<?xml version="1.0" encoding="UTF-8"?>
<testsuite name="test_1.CalcTest-20201117034406" tests="4" file="test_1.py" time="0.007" timestamp="2020-11-17T03:44:06" failures="1" errors="0" skipped="0">
	<testcase classname="test_1.CalcTest" name="test_div" time="0.001" timestamp="2020-11-17T03:44:06" file="test_1.py" line="15"/>
	<testcase classname="test_1.CalcTest" name="test_mul" time="0.000" timestamp="2020-11-17T03:44:06" file="test_1.py" line="12"/>
	<testcase classname="test_1.CalcTest" name="test_sub" time="0.000" timestamp="2020-11-17T03:44:06" file="test_1.py" line="9"/>
	<testcase classname="test_1.CalcTest" name="test_add" time="0.006" timestamp="2020-11-17T03:44:06" file="test_1.py" line="6">
		<failure type="AssertionError" message="6 != 3"><![CDATA[Traceback (most recent call last):
  File "D:\check\test_1.py", line 7, in test_add
    self.assertEqual(check.add(1, 5), 3)
AssertionError: 6 != 3
]]></failure>
	</testcase>
</testsuite>
